Workbook

Sheet 00_진행현황
A1: 스마트플레이스 세팅 정보 수집 시트
A2: 피부관리샵 전용 · 노란 칸에만 입력하시면 됩니다. 회색 칸은 자동으로 계산됩니다.
A4: 입력 방법 안내
A5: 노란 칸 | B5: 직접 입력하는 칸입니다.
A6: 회색 칸 | B6: 자동 계산되는 칸입니다. 수정하지 마세요.
A7: 회색 기울임 행 | B7: 각 시트 맨 윗줄의 예시입니다. 지우지 말고 그 아래부터 입력해 주세요.
A8: '필수' 표시 항목 | B8: 이 항목이 비어 있으면 세팅을 시작할 수 없습니다.
A9: 모르는 항목 | B9: 비워두고 상태를 '상담필요'로 선택해 주세요. 임의로 채우지 마세요.
A10: 중간 저장 | B10: 작성 도중 닫으셔도 됩니다. 받으신 링크로 다시 들어오면 이어서 작성할 수 있습니다.
A12: 업체 식별 정보
A13: 업체명 | B13: =IF('01_기본정보'!D5="","",'01_기본정보'!D5) | E13: 자동 | F13: 진입 화면에서 입력 · 01_기본정보와 연동
A14: 대표자명 | B14: =IF('01_기본정보'!D28="","",'01_기본정보'!D28) | E14: 자동 | F14: 진입 화면에서 입력 · 01_기본정보와 연동
A15: 본인확인 번호 | B15: =IF('01_기본정보'!D13="","",RIGHT('01_기본정보'!D13,4)) | E15: 자동 | F15: 휴대폰 뒷 4자리 · 재진입 시 본인 확인에 사용
A16: 세팅 ID | B16: =IF(OR(B13="",B14="",B15=""),"",B13&"_"&B14&"_"&B15) | E16: 자동 | F16: 업체명_대표자명_휴대폰뒷4자리 · 자동 생성 · 동명이인 구분에 사용
A17: 최초 제출일 | F17: 담당자 기입
A18: 최종 수정일 | F18: 담당자 기입
A19: 제출 버전 | F19: 1, 2, 3... 수정 제출할 때마다 올라갑니다
A20: 처리 상태 | F20: 접수 / 작업중 / 완료 / 변경요청
A21: 담당자
A22: 알림 수신 메일 | F22: 제출·수정 시 알림을 받을 주소
A24: 단계별 작성 현황
A25: 단계 | B25: 시트 | C25: 필수 여부 | D25: 입력 건수 | E25: 작성 상태 | F25: 비고
A26: 1. 기본정보 | B26: 01_기본정보 | C26: 필수 | D26: =COUNTA('01_기본정보'!D4:D29) -> 0 | E26: =IF(D26=0,"미작성","작성됨") -> 미작성 | F26: 상호·주소·전화·대표자명·홍보·상세설명·키워드
A27: 2. 부가정보 | B27: 02_부가정보 | C27: 권장 | D27: =COUNTA('02_부가정보'!D4:D38) -> 0 | E27: =IF(D27=0,"미작성","작성됨") -> 미작성 | F27: 시설·주차·장애인 편의·결제수단
A28: 3. 영업시간 | B28: 03_영업시간 | C28: 필수 | D28: =COUNTA('03_영업시간'!C5:C12) -> 0 | E28: =IF(D28=0,"미작성","작성됨") -> 미작성 | F28: 요일별 오픈 시각 기준
A29: 4. 시술메뉴 | B29: 04_시술마스터 | C29: 필수 | D29: =COUNTA('04_시술마스터'!C5:C44) -> 0 | E29: =IF(D29=0,"미작성","작성됨") -> 미작성 | F29: 등록된 시술 수
A30: 5. 패키지 | B30: 05_패키지 | C30: 선택 | D30: =COUNTA('05_패키지'!B5:B24) -> 0 | E30: =IF(D30=0,"미작성","작성됨") -> 미작성 | F30: 묶음 상품이 있을 때만
A31: 6. 예약상품 | B31: 06_예약상품 | C31: 권장 | D31: =COUNTA('06_예약상품'!B5:B44) -> 0 | E31: =IF(D31=0,"미작성","작성됨") -> 미작성 | F31: 예약을 받을 경우 필수
A32: 7. 예약설정 | B32: 07_예약설정 | C32: 권장 | D32: =COUNTA('07_예약설정'!D4:D48) -> 3 | E32: =IF(D32=0,"미작성","작성됨") -> 작성됨 | F32: 운영·첫방문이벤트·쿠폰·신규확인·알림·정보요청
A33: 8. 스마트콜 | B33: 08_스마트콜 | C33: 선택 | D33: =COUNTA('08_스마트콜'!D4:D28) -> 18 | E33: =IF(D33=0,"미작성","작성됨") -> 작성됨 | F33: 0507 번호 · 1차/2차 착신 · 기본 문구
A34: 9. 이미지 | B34: 09_이미지 | C34: 필수 | D34: =COUNTA('09_이미지'!D6:D125)+COUNTA('09_이미지'!D130)+COUNTA('09_이미지'!D135:D174) -> 0 | E34: =IF(D34=0,"미작성","작성됨") -> 미작성 | F34: 업체 사진 + 예약 메인 + 상품 이미지
A35: 전체 진행률 | D35: =COUNTIF(E26:E34,"작성됨")/9 -> 0.22222222 | E35: =IF(COUNTIFS(C26:C34,"필수",E26:E34,"작성됨")=COUNTIF(C26:C34,"필수"),"제출 가능","필수 항목 미완료") -> 필수 항목 미완료 | F35: 필수 단계(기본정보·영업시간·시술메뉴·이미지)가 모두 채워지면 담당자에게 메일이 발송됩니다

Sheet 01_기본정보
A1: 01. 기본정보
A2: 노란 칸에 입력해 주세요. 모르거나 아직 정하지 않은 항목은 비워두고 상태를 '상담필요'로 선택하시면 됩니다.
A3: 구분 | B3: 항목 | C3: 필수 | D3: 입력값 | E3: 상태 | F3: 입력 안내
A4: 업체 정보
A5: 업체 정보 | B5: 상호명 | C5: 필수 | F5: 지역명·홍보문구 금지 (네이버 심사 반려 사유). ❌ 강남 최고 피부관리 라온 | 예) 라온에스테틱
A6: 업체 정보 | B6: 지점명 | F6: 지점이 여러 개일 때만 | 예) 강남점
A7: 위치
A8: 위치 | B8: 주소(도로명) | C8: 필수 | F8: 우편번호 검색 결과 그대로 | 예) 서울 강남구 테헤란로 123
A9: 위치 | B9: 상세주소(층/호) | C9: 필수 | F9: 상가 입점이 대부분이라 층수 필수 | 예) 대한빌딩 3층 302호
A10: 위치 | B10: 찾아오는 길 | F10: 간판이 작거나 없으면 꼭 적어주세요 | 예) 1층 카페 옆 계단으로 3층
A11: 연락처
A12: 연락처 | B12: 대표 전화 | C12: 필수 | F12: ★ 스마트콜 0507 번호로 걸려온 전화가 이 번호로 연결됩니다 (1차 착신). 08_스마트콜 탭 참고 | 예) 02-1234-5678
A13: 연락처 | B13: 휴대폰 | C13: 필수 | F13: ★ 뒷 4자리가 재진입 시 본인 확인에 사용됩니다. 고객에게는 공개되지 않습니다 | 예) 010-1234-5678
A14: 연락처 | B14: 카카오톡 채널 | F14: 채널 URL | 예) http://pf.kakao.com/_abcd
A15: 홍보
A16: 홍보 | B16: 홈페이지 | F16: 예) https://raon.co.kr
A17: 홍보 | B17: 네이버 블로그 | F17: 블로그 주소 | 예) https://blog.naver.com/raon
A18: 홍보 | B18: 인스타그램 | F18: @핸들 또는 URL | 예) @raon_esthetic
A19: 홍보 | B19: 유튜브 | F19: 채널 주소 | 예) https://youtube.com/@raon
A20: 소개 · 키워드
A21: 소개 · 키워드 | B21: 업체 상세설명 | F21: =IF(D21="","2000자 이내. 시술 특징·차별점·이용 안내를 담아주세요. 예) 1:1 맞춤 케어로 피부 본연의 힘을 되찾아 드립니다. 10년 경력 원장이 직접 상담 후...","입력 "&LEN(D21)&" / 2000자"&IF(LEN(D21)>2000," ⚠ 글자 수 초과","")) -> 2000자 이내. 시술 특징·차별점·이용 안내를 담아주세요. 예) 1:1 맞춤 케어로 피부 본연의 힘을 되찾아 드립니다. 10년 경력 원장이 직접 상담 후...
A22: 소개 · 키워드 | B22: 대표 키워드 1 | F22: =IF(D22="","15자 이내. 예) 강남피부관리","입력 "&LEN(D22)&" / 15자"&IF(LEN(D22)>15," ⚠ 글자 수 초과","")) -> 15자 이내. 예) 강남피부관리
A23: 소개 · 키워드 | B23: 대표 키워드 2 | F23: =IF(D23="","15자 이내. 예) 등관리전문","입력 "&LEN(D23)&" / 15자"&IF(LEN(D23)>15," ⚠ 글자 수 초과","")) -> 15자 이내. 예) 등관리전문
A24: 소개 · 키워드 | B24: 대표 키워드 3 | F24: =IF(D24="","15자 이내. 예) 여드름케어","입력 "&LEN(D24)&" / 15자"&IF(LEN(D24)>15," ⚠ 글자 수 초과","")) -> 15자 이내. 예) 여드름케어
A25: 소개 · 키워드 | B25: 대표 키워드 4 | F25: =IF(D25="","15자 이내. 예) 왁싱","입력 "&LEN(D25)&" / 15자"&IF(LEN(D25)>15," ⚠ 글자 수 초과","")) -> 15자 이내. 예) 왁싱
A26: 소개 · 키워드 | B26: 대표 키워드 5 | F26: =IF(D26="","15자 이내. 예) 커플관리","입력 "&LEN(D26)&" / 15자"&IF(LEN(D26)>15," ⚠ 글자 수 초과","")) -> 15자 이내. 예) 커플관리
A27: 사업자 정보
A28: 사업자 정보 | B28: 대표자명 | C28: 필수 | F28: ★ 업체 식별 키로 사용됩니다. 반드시 입력 | 예) 홍길동
A29: 사업자 정보 | B29: 사업자등록번호 | F29: 10자리 | 예) 123-45-67890

Sheet 02_부가정보
A1: 02. 부가정보
A2: 편의시설은 Y / N 으로 선택해 주세요. 해당 없으면 N 입니다. 업체 상세설명·대표 키워드·홍보 채널(홈페이지·블로그·인스타그램·유튜브)은 '01_기본정보' 탭에 있습니다.
A3: 구분 | B3: 항목 | C3: 필수 | D3: 입력값 | E3: 상태 | F3: 입력 안내
A4: 시설 규모
A5: 시설 규모 | B5: 관리실(룸) 개수 | F5: 숫자만 | 예) 4
A6: 시설 규모 | B6: 관리사 인원 | F6: 동시 접수 가능 인원 산정에 사용 | 예) 3
A7: 시설 규모 | B7: 매장 평수 | F7: 예) 40
A8: 주차
A9: 주차 | B9: 자체 주차 가능 | F9: 건물 자체 주차장 이용 가능 여부. Y / N | 예) Y
A10: 주차 | B10: 주차 안내 | F10: =IF(D10="","400자 이내. 자체 주차장 이용 방법·무료 시간·주차 위치를 적어주세요. 예) 건물 지하 1~2층 이용, 2시간 무료. 입차 시 카운터에 차량번호를 알려주세요.","입력 "&LEN(D10)&" / 400자"&IF(LEN(D10)>400," ⚠ 글자 수 초과","")) -> 400자 이내. 자체 주차장 이용 방법·무료 시간·주차 위치를 적어주세요. 예) 건물 지하 1~2층 이용, 2시간 무료. 입차 시 카운터에 차량번호를 알려주세요.
A11: 주차 | B11: 인근 대체 주차장 이용 | F11: 자체 주차가 어려울 때 안내할 곳이 있으면 Y | 예) Y
A12: 주차 | B12: 대체 주차장 주소 | F12: 도로명 주소로 적어주세요. 여러 곳이면 줄바꿈으로 구분 | 예) 서울 강남구 테헤란로 130 대한공영주차장
A13: 주차 | B13: 주차비 지원 가능 | F13: 주차비를 대신 내주거나 할인해 주는 경우 Y | 예) Y
A14: 주차 | B14: 주차비 지원 조건 | F14: 금액·시간 조건을 함께 적어주세요 | 예) 5만원 이상 시술 시 2시간 지원
A15: 편의시설
A16: 편의시설 | B16: 개인룸 | F16: Y / N | 예) Y
A17: 편의시설 | B17: 샤워 시설 | F17: Y / N | 예) Y
A18: 편의시설 | B18: 와이파이 | F18: Y / N | 예) Y
A19: 편의시설 | B19: 여성 전용 | F19: Y / N | 예) N
A20: 편의시설 | B20: 남성 이용 가능 | F20: Y / N | 예) Y
A21: 편의시설 | B21: 예약제 운영 | F21: Y / N | 예) Y
A22: 장애인 편의시설
A23: 장애인 편의시설 | B23: 휠체어 이용 가능 출입구 | F23: 턱·계단 없이 진입 가능하면 Y. 경사로·엘리베이터 포함 | 예) Y
A24: 장애인 편의시설 | B24: 휠체어 이용 가능 화장실 | F24: 휠체어가 들어가고 회전할 수 있는 화장실 | 예) N
A25: 장애인 편의시설 | B25: 휠체어 이용 가능 좌석 | F25: 휠체어에서 이동하지 않고 이용 가능한 관리 베드·좌석 | 예) Y
A26: 장애인 편의시설 | B26: 장애인 전용 주차구역 | F26: 건물 또는 인근에 전용 구역이 있으면 Y | 예) Y
A27: 장애인 편의시설 | B27: 장애인 편의 안내 | F27: 위 항목으로 설명이 부족한 부분을 적어주세요 | 예) 엘리베이터로 3층 진입 가능, 화장실은 2층 공용 이용
A28: 결제수단
A29: 결제수단 | B29: 신용/체크카드 | F29: Y / N | 예) Y
A30: 결제수단 | B30: 현금영수증 | F30: Y / N | 예) Y
A31: 결제수단 | B31: 지역화폐 (지류) | F31: 종이 상품권 형태 | 예) Y
A32: 결제수단 | B32: 지역화폐 (카드) | F32: 충전식 카드 형태 | 예) Y
A33: 결제수단 | B33: 지역화폐 (모바일) | F33: 앱 QR·바코드 결제 | 예) N
A34: 결제수단 | B34: 지역화폐 종류 | F34: 취급하는 지역화폐 이름을 적어주세요 | 예) 서울사랑상품권
A35: 결제수단 | B35: 제로페이 | F35: Y / N | 예) Y
A36: 결제수단 | B36: 간편결제 | F36: Y / N | 예) Y
A37: 결제수단 | B37: 간편결제 종류 | F37: 받으시는 간편결제를 모두 적어주세요 | 예) 네이버페이, 카카오페이, 토스
A38: 결제수단 | B38: 고유가 지원금 | F38: Y / N | 예) N

Sheet 03_영업시간
A1: 03. 휴무일 · 영업시간
A2: 요일마다 다르지 않으면 첫 행만 채우고 나머지는 같은 값을 복사해 주세요. 시간은 24시 형식(예: 19:30)으로 적어주세요.
A3: 요일 | B3: 영업 여부 | C3: 오픈 | D3: 마감 | E3: 브레이크 시작 | F3: 브레이크 종료 | G3: 라스트오더 | H3: 비고
A4: 예시) | B4: Y | C4: 10:00 | D4: 21:00 | E4: 13:00 | F4: 14:00 | G4: 19:30 | H4: 브레이크타임 없으면 비워두세요
A5: 월요일
A6: 화요일
A7: 수요일
A8: 목요일
A9: 금요일
A10: 토요일
A11: 일요일
A12: 공휴일
A14: 추가 휴무 정보
A15: 정기 휴무 | F15: 예) 매주 월요일 / 매월 둘째·넷째 일요일
A16: 명절 휴무 | F16: 예) 설·추석 당일 휴무
A17: 연차·임시휴무 안내 방법 | F17: 예) 인스타그램 공지

Sheet 04_시술마스터
A1: 04. 시술 메뉴 (원본)
A2: ★ 모든 시술은 여기에 딱 한 번만 적습니다. 가격표·예약상품은 이 목록을 가져다 씁니다. 할인가는 여기 적지 마시고 '06_예약상품'에 적어주세요. 여기엔 정가만 넣습니다. 같은 시술의 시간 변형(60분·90분)은 각각 한 줄씩 적어주세요.
A3: No | B3: 카테고리 | C3: 시술명 (30자) | D3: 소요시간(분) | E3: 정가(원) | F3: 가격 부가설명 (96자) | G3: 시술 설명 (300자) | H3: 가격표 노출 | I3: 노출 순서 | J3: 사용 현황 (자동)
A4: 예시) | B4: 바디 | C4: 등 관리 | D4: 60 | E4: 80000 | F4: VAT 포함 · 회원가 기준 | G4: 노폐물 제거와 딥클렌징으로 등 트러블을 완화합니다. | H4: Y | I4: 1 | J4: 예약상품 2건 · 패키지 1건
A5: 1 | J5: =IF($C5="","","예약상품 "&COUNTIFS('06_예약상품'!$C$5:$C$44,"시술",'06_예약상품'!$D$5:$D$44,$C5)&"건 · 패키지 "&SUMPRODUCT(--ISNUMBER(SEARCH($C5,'05_패키지'!$C$5:$C$24)))&"건")
A6: 2 | J6: =IF($C6="","","예약상품 "&COUNTIFS('06_예약상품'!$C$5:$C$44,"시술",'06_예약상품'!$D$5:$D$44,$C6)&"건 · 패키지 "&SUMPRODUCT(--ISNUMBER(SEARCH($C6,'05_패키지'!$C$5:$C$24)))&"건")
A7: 3 | J7: =IF($C7="","","예약상품 "&COUNTIFS('06_예약상품'!$C$5:$C$44,"시술",'06_예약상품'!$D$5:$D$44,$C7)&"건 · 패키지 "&SUMPRODUCT(--ISNUMBER(SEARCH($C7,'05_패키지'!$C$5:$C$24)))&"건")
A8: 4 | J8: =IF($C8="","","예약상품 "&COUNTIFS('06_예약상품'!$C$5:$C$44,"시술",'06_예약상품'!$D$5:$D$44,$C8)&"건 · 패키지 "&SUMPRODUCT(--ISNUMBER(SEARCH($C8,'05_패키지'!$C$5:$C$24)))&"건")
A9: 5 | J9: =IF($C9="","","예약상품 "&COUNTIFS('06_예약상품'!$C$5:$C$44,"시술",'06_예약상품'!$D$5:$D$44,$C9)&"건 · 패키지 "&SUMPRODUCT(--ISNUMBER(SEARCH($C9,'05_패키지'!$C$5:$C$24)))&"건")
A10: 6 | J10: =IF($C10="","","예약상품 "&COUNTIFS('06_예약상품'!$C$5:$C$44,"시술",'06_예약상품'!$D$5:$D$44,$C10)&"건 · 패키지 "&SUMPRODUCT(--ISNUMBER(SEARCH($C10,'05_패키지'!$C$5:$C$24)))&"건")
A11: 7 | J11: =IF($C11="","","예약상품 "&COUNTIFS('06_예약상품'!$C$5:$C$44,"시술",'06_예약상품'!$D$5:$D$44,$C11)&"건 · 패키지 "&SUMPRODUCT(--ISNUMBER(SEARCH($C11,'05_패키지'!$C$5:$C$24)))&"건")
A12: 8 | J12: =IF($C12="","","예약상품 "&COUNTIFS('06_예약상품'!$C$5:$C$44,"시술",'06_예약상품'!$D$5:$D$44,$C12)&"건 · 패키지 "&SUMPRODUCT(--ISNUMBER(SEARCH($C12,'05_패키지'!$C$5:$C$24)))&"건")
A13: 9 | J13: =IF($C13="","","예약상품 "&COUNTIFS('06_예약상품'!$C$5:$C$44,"시술",'06_예약상품'!$D$5:$D$44,$C13)&"건 · 패키지 "&SUMPRODUCT(--ISNUMBER(SEARCH($C13,'05_패키지'!$C$5:$C$24)))&"건")
A14: 10 | J14: =IF($C14="","","예약상품 "&COUNTIFS('06_예약상품'!$C$5:$C$44,"시술",'06_예약상품'!$D$5:$D$44,$C14)&"건 · 패키지 "&SUMPRODUCT(--ISNUMBER(SEARCH($C14,'05_패키지'!$C$5:$C$24)))&"건")
A15: 11 | J15: =IF($C15="","","예약상품 "&COUNTIFS('06_예약상품'!$C$5:$C$44,"시술",'06_예약상품'!$D$5:$D$44,$C15)&"건 · 패키지 "&SUMPRODUCT(--ISNUMBER(SEARCH($C15,'05_패키지'!$C$5:$C$24)))&"건")
A16: 12 | J16: =IF($C16="","","예약상품 "&COUNTIFS('06_예약상품'!$C$5:$C$44,"시술",'06_예약상품'!$D$5:$D$44,$C16)&"건 · 패키지 "&SUMPRODUCT(--ISNUMBER(SEARCH($C16,'05_패키지'!$C$5:$C$24)))&"건")
... A44: 40 | J44: =IF($C44="","","예약상품 "&COUNTIFS('06_예약상품'!$C$5:$C$44,"시술",'06_예약상품'!$D$5:$D$44,$C44)&"건 · 패키지 "&SUMPRODUCT(--ISNUMBER(SEARCH($C44,'05_패키지'!$C$5:$C$24)))&"건")

Sheet 05_패키지
A1: 05. 패키지 (시술 묶음)
A2: '04_시술마스터'의 시술을 묶어 파는 상품입니다. ▸ 구성 시술의 '회'는 1세트 안에서 몇 번 받는지, '반복 횟수'는 그 세트를 몇 번 파는지입니다. 등관리 10회권처럼 단일 시술 회차권은 구성 시술 1개 + 반복 10회로 적어주세요. 개별 합계는 (시술 정가 × 세트 내 횟수)를 모두 더한 뒤 반복 횟수를 곱한 금액입니다. 할인율은 자동 계산됩니다.
A3: No | B3: 패키지명 (30자) | C3: 구성 시술 | D3: 반복 횟수 | E3: 개별 합계(원) | F3: 판매가(원) | G3: 할인율 | H3: 총 소요시간(분) | I3: 유효기간 | J3: 설명 (300자) | K3: 사용 현황 (자동)
A4: 예시) | B4: 등+각질 케어 세트 | C4: 등 관리 1회 + 바디 각질제거 1회 | D4: 5 | E4: 800000 | F4: 600000 | G4: 0.25 | H4: 450 | I4: 3개월 | J4: 첫 방문 고객에게 인기 있는 조합 | K4: 예약상품 1건
A5: 1 | G5: =IFERROR((E5-F5)/E5,"") | K5: =IF($B5="","","예약상품 "&COUNTIFS('06_예약상품'!$C$5:$C$44,"패키지",'06_예약상품'!$D$5:$D$44,$B5)&"건")
A6: 2 | G6: =IFERROR((E6-F6)/E6,"") | K6: =IF($B6="","","예약상품 "&COUNTIFS('06_예약상품'!$C$5:$C$44,"패키지",'06_예약상품'!$D$5:$D$44,$B6)&"건")
A7: 3 | G7: =IFERROR((E7-F7)/E7,"") | K7: =IF($B7="","","예약상품 "&COUNTIFS('06_예약상품'!$C$5:$C$44,"패키지",'06_예약상품'!$D$5:$D$44,$B7)&"건")
A8: 4 | G8: =IFERROR((E8-F8)/E8,"") | K8: =IF($B8="","","예약상품 "&COUNTIFS('06_예약상품'!$C$5:$C$44,"패키지",'06_예약상품'!$D$5:$D$44,$B8)&"건")
A9: 5 | G9: =IFERROR((E9-F9)/E9,"") | K9: =IF($B9="","","예약상품 "&COUNTIFS('06_예약상품'!$C$5:$C$44,"패키지",'06_예약상품'!$D$5:$D$44,$B9)&"건")
A10: 6 | G10: =IFERROR((E10-F10)/E10,"") | K10: =IF($B10="","","예약상품 "&COUNTIFS('06_예약상품'!$C$5:$C$44,"패키지",'06_예약상품'!$D$5:$D$44,$B10)&"건")
A11: 7 | G11: =IFERROR((E11-F11)/E11,"") | K11: =IF($B11="","","예약상품 "&COUNTIFS('06_예약상품'!$C$5:$C$44,"패키지",'06_예약상품'!$D$5:$D$44,$B11)&"건")
A12: 8 | G12: =IFERROR((E12-F12)/E12,"") | K12: =IF($B12="","","예약상품 "&COUNTIFS('06_예약상품'!$C$5:$C$44,"패키지",'06_예약상품'!$D$5:$D$44,$B12)&"건")
A13: 9 | G13: =IFERROR((E13-F13)/E13,"") | K13: =IF($B13="","","예약상품 "&COUNTIFS('06_예약상품'!$C$5:$C$44,"패키지",'06_예약상품'!$D$5:$D$44,$B13)&"건")
A14: 10 | G14: =IFERROR((E14-F14)/E14,"") | K14: =IF($B14="","","예약상품 "&COUNTIFS('06_예약상품'!$C$5:$C$44,"패키지",'06_예약상품'!$D$5:$D$44,$B14)&"건")
A15: 11 | G15: =IFERROR((E15-F15)/E15,"") | K15: =IF($B15="","","예약상품 "&COUNTIFS('06_예약상품'!$C$5:$C$44,"패키지",'06_예약상품'!$D$5:$D$44,$B15)&"건")
A16: 12 | G16: =IFERROR((E16-F16)/E16,"") | K16: =IF($B16="","","예약상품 "&COUNTIFS('06_예약상품'!$C$5:$C$44,"패키지",'06_예약상품'!$D$5:$D$44,$B16)&"건")
... A24: 20 | G24: =IFERROR((E24-F24)/E24,"") | K24: =IF($B24="","","예약상품 "&COUNTIFS('06_예약상품'!$C$5:$C$44,"패키지",'06_예약상품'!$D$5:$D$44,$B24)&"건")

Sheet 06_예약상품
A1: 06. 예약 상품 (실제 판매 형태)
A2: 같은 시술이라도 파는 방식이 다르면 각각 한 줄씩 적어주세요. 예) '등 관리'를 ①정가 예약 ②첫방문 체험가 로 판다면 2줄이 됩니다. ★ 회차권·10회권은 여기가 아니라 '05_패키지'에서 만듭니다. 만든 패키지를 대상으로 골라 예약을 받으세요. 재방문 고객이 예약할 수 있도록 시술마다 '정가 판매' 한 줄은 꼭 넣어주세요.
A3: No | B3: 예약상품명 (30자) | C3: 대상 구분 | D3: 대상명 | E3: 포함 시술 (자동) | F3: 판매 유형 | G3: 정가(원) | H3: 판매가(원) | I3: 할인율 | J3: 구매 대상 | K3: 1인 구매 제한 | L3: 판매 시작일 | M3: 판매 종료일 | N3: 소요시간(분) | O3: 예약금(원) | P3: 동시 접수 인원
A4: 예시) | B4: 첫방문 세트 체험 | C4: 패키지 | D4: 등+각질 케어 세트 | E4: 등 관리 1회 + 바디 각질제거 1회 | F4: 첫방문 체험 | G4: 800000 | H4: 300000 | I4: 0.625 | J4: 신규만 | K4: 1회 | L4: 상시 | M4: 상시 | N4: 90 | O4: 30000 | P4: 2
A5: 1 | E5: =IF($D5="","",IF($C5="시술",$D5,IFERROR(INDEX('05_패키지'!$C$5:$C$24,MATCH($D5,'05_패키지'!$B$5:$B$24,0)),"⚠ 05_패키지에서 못 찾음"))) | I5: =IFERROR((G5-H5)/G5,"")
A6: 2 | E6: =IF($D6="","",IF($C6="시술",$D6,IFERROR(INDEX('05_패키지'!$C$5:$C$24,MATCH($D6,'05_패키지'!$B$5:$B$24,0)),"⚠ 05_패키지에서 못 찾음"))) | I6: =IFERROR((G6-H6)/G6,"")
A7: 3 | E7: =IF($D7="","",IF($C7="시술",$D7,IFERROR(INDEX('05_패키지'!$C$5:$C$24,MATCH($D7,'05_패키지'!$B$5:$B$24,0)),"⚠ 05_패키지에서 못 찾음"))) | I7: =IFERROR((G7-H7)/G7,"")
A8: 4 | E8: =IF($D8="","",IF($C8="시술",$D8,IFERROR(INDEX('05_패키지'!$C$5:$C$24,MATCH($D8,'05_패키지'!$B$5:$B$24,0)),"⚠ 05_패키지에서 못 찾음"))) | I8: =IFERROR((G8-H8)/G8,"")
A9: 5 | E9: =IF($D9="","",IF($C9="시술",$D9,IFERROR(INDEX('05_패키지'!$C$5:$C$24,MATCH($D9,'05_패키지'!$B$5:$B$24,0)),"⚠ 05_패키지에서 못 찾음"))) | I9: =IFERROR((G9-H9)/G9,"")
A10: 6 | E10: =IF($D10="","",IF($C10="시술",$D10,IFERROR(INDEX('05_패키지'!$C$5:$C$24,MATCH($D10,'05_패키지'!$B$5:$B$24,0)),"⚠ 05_패키지에서 못 찾음"))) | I10: =IFERROR((G10-H10)/G10,"")
A11: 7 | E11: =IF($D11="","",IF($C11="시술",$D11,IFERROR(INDEX('05_패키지'!$C$5:$C$24,MATCH($D11,'05_패키지'!$B$5:$B$24,0)),"⚠ 05_패키지에서 못 찾음"))) | I11: =IFERROR((G11-H11)/G11,"")
A12: 8 | E12: =IF($D12="","",IF($C12="시술",$D12,IFERROR(INDEX('05_패키지'!$C$5:$C$24,MATCH($D12,'05_패키지'!$B$5:$B$24,0)),"⚠ 05_패키지에서 못 찾음"))) | I12: =IFERROR((G12-H12)/G12,"")
A13: 9 | E13: =IF($D13="","",IF($C13="시술",$D13,IFERROR(INDEX('05_패키지'!$C$5:$C$24,MATCH($D13,'05_패키지'!$B$5:$B$24,0)),"⚠ 05_패키지에서 못 찾음"))) | I13: =IFERROR((G13-H13)/G13,"")
A14: 10 | E14: =IF($D14="","",IF($C14="시술",$D14,IFERROR(INDEX('05_패키지'!$C$5:$C$24,MATCH($D14,'05_패키지'!$B$5:$B$24,0)),"⚠ 05_패키지에서 못 찾음"))) | I14: =IFERROR((G14-H14)/G14,"")
A15: 11 | E15: =IF($D15="","",IF($C15="시술",$D15,IFERROR(INDEX('05_패키지'!$C$5:$C$24,MATCH($D15,'05_패키지'!$B$5:$B$24,0)),"⚠ 05_패키지에서 못 찾음"))) | I15: =IFERROR((G15-H15)/G15,"")
A16: 12 | E16: =IF($D16="","",IF($C16="시술",$D16,IFERROR(INDEX('05_패키지'!$C$5:$C$24,MATCH($D16,'05_패키지'!$B$5:$B$24,0)),"⚠ 05_패키지에서 못 찾음"))) | I16: =IFERROR((G16-H16)/G16,"")
... A44: 40 | E44: =IF($D44="","",IF($C44="시술",$D44,IFERROR(INDEX('05_패키지'!$C$5:$C$24,MATCH($D44,'05_패키지'!$B$5:$B$24,0)),"⚠ 05_패키지에서 못 찾음"))) | I44: =IFERROR((G44-H44)/G44,"")

Sheet 07_예약설정
A1: 07. 예약 설정
A2: 아직 정하지 않으신 항목은 비워두고 상태를 '상담필요'로 선택해 주세요. 담당자가 함께 정해드립니다. ★ 첫방문 이벤트는 '쿠폰 발급'과 '예약상품 할인' 중 하나만 쓸 수 있습니다. 쿠폰을 쓰시면 06_예약상품에는 정가만 넣고, 예약상품 할인을 쓰시면 쿠폰 상세는 비워두세요.
A3: 구분 | B3: 항목 | C3: 필수 | D3: 입력값 | E3: 상태 | F3: 입력 안내
A4: 운영 설정
A5: 운영 설정 | B5: 온라인 예약 사용 | C5: 필수 | F5: N 이면 아래 항목은 비워두셔도 됩니다 | 예) Y
A6: 운영 설정 | B6: 예약 가능 시작 | F6: 예) 당일부터 / 익일부터 / 2일 후부터 | 예) 당일부터
A7: 운영 설정 | B7: 예약 가능 종료 | F7: 얼마나 먼 날짜까지 열어둘지 | 예) 30일 후까지
A8: 운영 설정 | B8: 예약 마감 시점 | F8: 이 시점 이후에는 예약을 받지 않습니다 | 예) 시작 2시간 전
A9: 운영 설정 | B9: 취소 가능 시점 | F9: 예) 시작 24시간 전
A10: 운영 설정 | B10: 예약 시간 단위 | F10: 30분 / 60분 | 예) 30분
A11: 운영 설정 | B11: 동시 예약 가능 건수 | F11: 관리사 인원 기준 | 예) 2
A12: 운영 설정 | B12: 노쇼 정책 | F12: 예약금을 받는 경우 꼭 정해주세요 | 예) 예약금 환불 불가
A13: 첫방문 이벤트
A14: 첫방문 이벤트 | B14: 첫방문 이벤트 사용 | F14: N 이면 아래 항목은 비워두셔도 됩니다
A15: 첫방문 이벤트 | B15: 이벤트 방식 | F15: ★ 둘 중 하나만 선택할 수 있습니다. 쿠폰과 예약상품 할인을 동시에 쓰면 할인이 두 번 적용됩니다
A16: 쿠폰 상세
A17: 쿠폰 상세 | B17: 할인 방식 | F17: '이벤트 방식 = 쿠폰 발급'일 때만 작성
A18: 쿠폰 상세 | B18: 할인 값 | F18: 정액이면 원 단위, 정률이면 % 숫자만 | 예) 50000
A19: 쿠폰 상세 | B19: 적용 대상 시술 | F19: 특정 시술만이면 시술명을 적어주세요 | 예) 전체 시술
A20: 쿠폰 상세 | B20: 최소 결제 금액 | F20: 조건이 없으면 0 | 예) 50000
A21: 쿠폰 상세 | B21: 다른 할인과 중복 사용 | F21: Y / N
A22: 쿠폰 상세 | B22: 쿠폰 유효기간 | F22: 예) 발급일로부터 30일
A23: 쿠폰 상세 | B23: 쿠폰 발급 경로 | F23: 예) 네이버 예약 쿠폰 + 문자 발송
A24: 신규 고객 확인
A25: 신규 고객 확인 | B25: 신규 판정 방식 | F25: 첫방문 혜택을 누구에게 줄지 판단하는 방법입니다. 원장님이 선택해 주세요
A26: 신규 고객 확인 | B26: 신규 확인 안내 문구 | F26: =IF(D26="","300자 이내. 고객에게 보여줄 안내입니다. 신규 확인 방법과 준비물을 적어주세요. 예) 첫방문 체험가는 본 매장 첫 이용 고객만 받으실 수 있습니다. 방문 시 신분 확인이 있을 수 있습니다.","입력 "&LEN(D26)&" / 300자"&IF(LEN(D26)>300," ⚠ 글자 수 초과","")) -> 300자 이내. 고객에게 보여줄 안내입니다. 신규 확인 방법과 준비물을 적어주세요. 예) 첫방문 체험가는 본 매장 첫 이용 고객만 받으실 수 있습니다. 방문 시 신분 확인이 있을 수 있습니다.
A27: 신규 고객 확인 | B27: 신규가 아닐 경우 처리 | F27: 현장에서 신규가 아닌 것으로 확인됐을 때
A28: 알림 설정
A29: 알림 설정 | B29: 알림톡 사용 | F29: Y / N | 예) Y
A30: 알림 설정 | B30: 예약 확정 알림 | F30: 고객에게 즉시 발송 | 예) Y
A31: 알림 설정 | B31: 예약 확정 안내 문구 | F31: =IF(D31="","500자 이내. 예약이 확정됐을 때 고객에게 보낼 문구입니다. 준비물·주차·방문 안내를 담아주세요. 예) 예약이 확정되었습니다. 편한 복장으로 10분 전 도착 부탁드립니다. 주차는 건물 지하 2시간 무료입니다.","입력 "&LEN(D31)&" / 500자"&IF(LEN(D31)>500," ⚠ 글자 수 초과","")) -> 500자 이내. 예약이 확정됐을 때 고객에게 보낼 문구입니다. 준비물·주차·방문 안내를 담아주세요. 예) 예약이 확정되었습니다. 편한 복장으로 10분 전 도착 부탁드립니다. 주차는 건물 지하 2시간 무료입니다.
A32: 알림 설정 | B32: 리마인드 1차 시점 | D32: 1일 전 | F32: 방문 며칠 전에 알려드릴지 선택해 주세요
A33: 알림 설정 | B33: 리마인드 1차 발송 시각 | D33: 오후 6시 | F33: 그날 몇 시에 보낼지 선택해 주세요
A34: 알림 설정 | B34: 리마인드 2차 시점 | D34: 미발송 | F34: 한 번만 보내시려면 '미발송'을 선택하세요
A35: 알림 설정 | B35: 리마인드 2차 발송 시각 | F35: 2차를 사용할 때만
A36: 알림 설정 | B36: 리마인드 안내 문구 | F36: =IF(D36="","500자 이내. 방문 전에 보낼 문구입니다. 방문 일시·준비물·주차 안내를 담아주세요. 예) 내일 오후 3시 등 관리 예약이 있습니다. 편한 복장으로 10분 전 도착 부탁드립니다.","입력 "&LEN(D36)&" / 500자"&IF(LEN(D36)>500," ⚠ 글자 수 초과","")) -> 500자 이내. 방문 전에 보낼 문구입니다. 방문 일시·준비물·주차 안내를 담아주세요. 예) 내일 오후 3시 등 관리 예약이 있습니다. 편한 복장으로 10분 전 도착 부탁드립니다.
A37: 알림 설정 | B37: 취소 알림 | F37: Y / N | 예) Y
A38: 알림 설정 | B38: 예약 취소 안내 문구 | F38: =IF(D38="","500자 이내. 예약이 취소됐을 때 보낼 문구입니다. 재예약 안내·환불 기준을 담아주세요. 예) 예약이 취소되었습니다. 재예약은 네이버 예약 또는 전화로 가능합니다. 예약금은 3영업일 내 환불됩니다.","입력 "&LEN(D38)&" / 500자"&IF(LEN(D38)>500," ⚠ 글자 수 초과","")) -> 500자 이내. 예약이 취소됐을 때 보낼 문구입니다. 재예약 안내·환불 기준을 담아주세요. 예) 예약이 취소되었습니다. 재예약은 네이버 예약 또는 전화로 가능합니다. 예약금은 3영업일 내 환불됩니다.
A39: 알림 설정 | B39: 관리자 수신 번호 | F39: 새 예약이 들어올 때 받을 번호 | 예) 010-1234-5678
A40: 예약자 정보요청
...

Sheet 08_스마트콜
A1: 08. 스마트콜
A2: 선택 서비스입니다. 사용하지 않으시면 '스마트콜 사용'만 N 으로 표시하고 넘어가셔도 됩니다. ★ 분기 멘트에는 기본 문구가 미리 입력되어 있습니다. 우리 샵에 맞게 고쳐야 할 부분만 수정해 주세요. ▸ 통화 흐름: 고객이 0507 번호로 전화 → 1차 연결 번호(01_기본정보 대표 전화)로 착신 → 받지 않으면 2차 연결 번호로 전환됩니다.
A3: 구분 | B3: 항목 | C3: 필수 | D3: 입력값 | E3: 상태 | F3: 입력 안내
A4: 스마트 ARS
A5: 스마트 ARS | B5: 스마트콜 사용 | F5: N 이면 아래 항목은 비워두셔도 됩니다 | 예) Y
A6: 스마트 ARS | B6: 스마트콜 번호 (0507) | F6: 네이버가 발급하는 번호로, 고객에게는 이 번호가 보입니다. 아직 없으면 비워두세요 (담당자가 발급) | 예) 0507-1234-5678
A7: 스마트 ARS | B7: 1차 연결 번호 | D7: =IF('01_기본정보'!D12="","",'01_기본정보'!D12) | F7: 01_기본정보 > 연락처 > 대표 전화가 자동으로 사용됩니다
A8: 스마트 ARS | B8: 2차 연결 번호 | F8: 1차 번호로 연결되지 않을 때 대신 받을 번호입니다. 원장님 개인 휴대폰 등 | 예) 010-9876-5432
A9: 스마트 ARS | B9: 2차 전환 대기 시간 | D9: 20초 | F9: 1차 번호가 이 시간 동안 안 받으면 2차로 넘어갑니다
A10: 스마트 ARS | B10: 인사 멘트 | D10: 안녕하세요, 라온에스테틱입니다. | F10: 전화 연결 시 가장 먼저 나오는 안내입니다
A11: ARS 분기
A12: 1번 통화연결 | B12: 사용 여부 | D12: Y | F12: 1번은 상담원 연결입니다. 끄시면 다른 분기의 '1번을 눌러주세요' 안내도 빼야 합니다
A13: 1번 통화연결 | B13: 안내 멘트 | D13: 상담원을 연결해 드리겠습니다. 잠시만 기다려 주세요. | F13: 연결 직전에 나올 안내
A14: 2번 예약안내 | B14: 사용 여부 | D14: Y | F14: Y / N
A15: 2번 예약안내 | B15: 안내 멘트 | D15: 네이버 예약 방법이 문자로 발송되었습니다. 통화 연결을 원하시면 1번을 눌러주세요. | F15: 네이버 예약 방법 안내 후 문자 발송
A16: 3번 오시는길 | B16: 사용 여부 | D16: Y | F16: Y / N
A17: 3번 오시는길 | B17: 안내 멘트 | D17: 찾아오시는 길 정보가 문자로 발송되었습니다. 통화 연결을 원하시면 1번을 눌러주세요. | F17: 찾아오는 길 안내 후 문자 발송
A18: 4번 주차안내 | B18: 사용 여부 | D18: Y | F18: Y / N
A19: 4번 주차안내 | B19: 안내 멘트 | D19: 주차는 건물 지하 주차장을 이용하시면 됩니다. 주차 요금은 1시간 30분 동안 무료입니다. 통화 연결을 원하시면 1번을 눌러주세요. | F19: 02_부가정보의 주차 내용과 일치시켜 주세요
A20: 5번 영업시간 | B20: 사용 여부 | D20: Y | F20: Y / N
A21: 5번 영업시간 | B21: 안내 멘트 | D21: 영업시간은 평일 오전 7시부터 오후 10시까지이며, 휴일은 오전 8시부터 오후 8시까지입니다. 일요일은 18시까지입니다. 통화 연결을 원하시면 1번을 눌러주세요. | F21: 03_영업시간 탭과 일치시켜 주세요
A22: 기타 안내
A23: 기타 안내 | B23: 영업시간 외 안내 | D23: 지금은 영업시간이 아닙니다. 예약은 네이버에서 24시간 가능합니다. | F23: 영업시간이 아닐 때 나올 안내
A24: 기타 안내 | B24: 부재중 안내 | D24: 시술 중이라 전화를 받지 못했습니다. 문자 남겨주시면 확인 후 회신드리겠습니다. | F24: 받지 못했을 때 나올 안내
A25: 통화 연결음
A26: 통화 연결음 | B26: 통화 연결음 사용 | D26: Y | F26: Y / N
A27: 통화 연결음 | B27: 연결음 멘트 | D27: 안녕하세요, 라온에스테틱입니다. 이달의 첫방문 체험 이벤트를 진행 중입니다. 자세한 내용은 네이버 스마트플레이스에서 확인하실 수 있습니다. 잠시만 기다려 주세요. | F27: 고객이 연결을 기다리는 동안 나옵니다. 홍보 문구를 넣을 수 있습니다
A28: 통화 연결음 | B28: 배경 음악 | D28: 잔잔하고 편안한 분위기 | F28: 선호하는 분위기를 적어주세요

Sheet 09_이미지
A1: 09. 이미지 목록
A2: 사진 파일은 함께 안내드린 구글 드라이브 폴더에 올려주세요. 이 표에는 어떤 사진인지만 적어주시면 됩니다. ★ 모든 이미지는 장당 20MB 이하여야 합니다. 드라이브 링크는 담당자가 채웁니다.
A3: ① 업체 사진 · 스마트플레이스 메인 화면 노출 · 최대 120장 · 장당 20MB
A4: No | B4: 구분 | C4: 세부 용도 · 연결 대상 | D4: 파일명 | E4: 대표 여부 | F4: 노출 순서 | G4: 드라이브 링크 | H4: 비고
A5: 예시) | B5: 업체 사진 | C5: 외관 | D5: 외관_01.jpg | E5: Y | F5: 1 | G5: (담당자가 채웁니다) | H5: 간판이 잘 보이는 사진
A6: 1 | B6: 업체 사진
A7: 2 | B7: 업체 사진
A8: 3 | B8: 업체 사진
A9: 4 | B9: 업체 사진
A10: 5 | B10: 업체 사진
A11: 6 | B11: 업체 사진
A12: 7 | B12: 업체 사진
A13: 8 | B13: 업체 사진
A14: 9 | B14: 업체 사진
A15: 10 | B15: 업체 사진
A16: 11 | B16: 업체 사진
A17: 12 | B17: 업체 사진
... A125: 120 | B125: 업체 사진
A127: ② 예약 메인 이미지 · 네이버 예약 메인 화면 노출 · 1장 · 20MB
A128: No | B128: 구분 | C128: 세부 용도 · 연결 대상 | D128: 파일명 | E128: 대표 여부 | F128: 노출 순서 | G128: 드라이브 링크 | H128: 비고
A129: 예시) | B129: 예약 메인 | C129: — | D129: 예약메인_01.jpg | E129: — | F129: — | G129: (담당자가 채웁니다) | H129: 가로형 권장
A130: 1 | B130: 예약 메인
A132: ③ 예약 상품 이미지 · 예약 상품별 노출 · 상품당 1장 · 20MB
A133: No | B133: 구분 | C133: 세부 용도 · 연결 대상 | D133: 파일명 | E133: 대표 여부 | F133: 노출 순서 | G133: 드라이브 링크 | H133: 비고
A134: 예시) | B134: 예약 상품 | C134: 첫방문 등관리 체험 | D134: 상품_등관리체험.jpg | E134: — | F134: 1 | G134: (담당자가 채웁니다) | H134: 06_예약상품의 예약상품명과 똑같이 적어주세요
A135: 1 | B135: 예약 상품
A136: 2 | B136: 예약 상품
A137: 3 | B137: 예약 상품
A138: 4 | B138: 예약 상품
A139: 5 | B139: 예약 상품
A140: 6 | B140: 예약 상품
A141: 7 | B141: 예약 상품
A142: 8 | B142: 예약 상품
A143: 9 | B143: 예약 상품
A144: 10 | B144: 예약 상품
A145: 11 | B145: 예약 상품
A146: 12 | B146: 예약 상품
... A174: 40 | B174: 예약 상품

Sheet 10_변경이력
A1: 10. 변경 이력 · 버전 관리
A2: 이 탭은 시스템이 자동으로 기록합니다. 사장님은 입력하지 않으셔도 됩니다. 담당자는 '담당자 확인' 열과 '비고'만 사용하세요. ★ 복원은 이전 버전을 덮어쓰지 않고 새 버전으로 만듭니다. 이력은 절대 지워지지 않습니다.
A4: 버전 목록 (복원 지점)
A5: 버전 | B5: 제출 일시 | C5: 완성도 | D5: 변경 건수 | E5: 처리 상태 | F5: 스냅샷 ID | G5: 복원 여부 | H5: 비고 | I5: 담당자
A6: 예시) | B6: 2026-08-13 14:22 | C6: 0.78 | D6: 0 | E6: 접수 | F6: snap_a1b2c3 | G6: — | H6: 최초 제출 | I6: 김담당
A7: v1
A8: v2
A9: v3
A10: v4
A11: v5
A12: v6
A13: v7
A14: v8
A15: v9
A16: v10
A17: v11
A18: v12
... A23: 변경 상세
A24: No | B24: 일시 | C24: 버전 | D24: 탭 | E24: 항목 | F24: 이전 값 | G24: 새 값 | H24: 변경 주체 | I24: 담당자 확인
A25: 예시) | B25: 2026-08-15 09:10 | C25: v2 | D25: 01_기본정보 | E25: 대표 전화 | F25: 02-1234-5678 | G25: 02-1234-9999 | H25: 사장님 | I25: 확인
A26: 1
A27: 2
A28: 3
A29: 4
A30: 5
A31: 6
A32: 7
A33: 8
A34: 9
A35: 10
A36: 11
A37: 12
... A85: 60
